<?xml version="1.0"?>
<robot name="rb_y1_right_arm">

  <!-- Links -->

  <link name="link_right_arm_base" />

  <link name="link_right_arm_0">
    <inertial>
      <mass value="1.26164242" />
      <origin rpy="0 0 0" xyz="-0.00316662 0.03437181 -0.00000030" />
      <inertia ixx="0.00230621" ixy="0.00039024" ixz="-0.00000256" iyy="0.00426418" iyz="0.00000118"
        izz="0.00432156" />
    </inertial>

    <visual>
      <origin xyz="0 0 0" rpy="1.57079632679 0 0" />
      <geometry>
        <mesh filename="package://qr_assets/rby1_description_drake/meshes/LINK_7.obj" />
      </geometry>
    </visual>

    <collision>
        <origin xyz="0.025 0.018 -0.005" rpy="0 0 0" />
        <geometry>
            <sphere radius="0.075" />
        </geometry>
    </collision>
    <collision>
        <origin xyz="-0.015 0.018 -0.005" rpy="0 0 0" />
        <geometry>
            <sphere radius="0.075" />
        </geometry>
    </collision>
    <collision>
        <origin xyz="-0.05 0.018 -0.005" rpy="0 0 0" />
        <geometry>
            <sphere radius="0.075" />
        </geometry>
    </collision>
  </link>

  <link name="link_right_arm_1">
    <inertial>
      <mass value="2.27287031" />
      <origin rpy="0 0 0" xyz="-0.00307855 -0.00124741 -0.01294324" />
      <inertia ixx="0.00388490" ixy="-0.00001477" ixz="0.00011465" iyy="0.00447034"
        iyz="-0.00010023" izz="0.00288341" />
    </inertial>

    <visual>
      <origin xyz="0 0 0" rpy="1.57079632679 0 0" />
      <geometry>
        <mesh filename="package://qr_assets/rby1_description_drake/meshes/LINK_8.obj" />
      </geometry>
    </visual>

    <collision>
      <origin xyz="0 0 -0.07" rpy="0 0 0" />
      <geometry>
        <sphere radius="0.05" />
      </geometry>
    </collision>
  </link>

  <link name="link_right_arm_2">
    <inertial>
      <mass value="2.46909439" />
      <origin rpy="0 0 0" xyz="0.00115434 -0.00196635 -0.16192524" />
      <inertia ixx="0.00980269" ixy="0.00005871" ixz="0.00051888" iyy="0.00924560" iyz="-0.00045932"
        izz="0.00329867" />
    </inertial>

    <visual>
      <origin xyz="0 0 0" rpy="1.57079632679 0 0" />
      <geometry>
        <mesh filename="package://qr_assets/rby1_description_drake/meshes/LINK_9.obj" />
      </geometry>
    </visual>

    <collision>
      <origin xyz="0 0 -0.11" rpy="0 0 0" />
      <geometry>
        <sphere radius="0.05" />
      </geometry>
    </collision>
    <collision>
      <origin xyz="0 0 -0.15" rpy="0 0 0" />
      <geometry>
        <sphere radius="0.05" />
      </geometry>
    </collision>
    <collision>
      <origin xyz="0 0 -0.19" rpy="0 0 0" />
      <geometry>
        <sphere radius="0.05" />
      </geometry>
    </collision>
    <collision>
      <origin xyz="0 0 -0.23" rpy="0 0 0" />
      <geometry>
        <sphere radius="0.05" />
      </geometry>
    </collision>

    <collision>
      <origin xyz="0 0.022 -0.24" rpy="0 0 0" />
      <geometry>
        <sphere radius="0.05" />
      </geometry>
    </collision>
    <collision>
      <origin xyz="0 -0.02 -0.24" rpy="0 0 0" />
      <geometry>
        <sphere radius="0.05" />
      </geometry>
    </collision>

    <collision>
      <origin xyz="0.031 0.042 -0.275" rpy="0 0 0" />
      <geometry>
        <sphere radius="0.045" />
      </geometry>
    </collision>
    <collision>
      <origin xyz="0.031 -0.04 -0.275" rpy="0 0 0" />
      <geometry>
        <sphere radius="0.045" />
      </geometry>
    </collision>
  </link>

  <link name="link_right_arm_3">
    <inertial>
      <mass value="2.26099493" />
      <origin rpy="0 0 0" xyz="-0.01603135 -0.00692891 -0.04549811" />
      <inertia ixx="0.00822606" ixy="0.00027620" ixz="-0.00156570" iyy="0.00844870" iyz="0.00076157"
        izz="0.00236614" />
    </inertial>

    <visual>
      <origin xyz="0 0 0" rpy="1.57079632679 0 0" />
      <geometry>
        <mesh filename="package://qr_assets/rby1_description_drake/meshes/LINK_10.obj" />
      </geometry>
    </visual>

    <collision>
      <origin xyz="-0.015 0 0" rpy="0 0 0" />
      <geometry>
        <sphere radius="0.06" />
      </geometry>
    </collision>

    <collision>
      <origin xyz="-0.031 0 -0.06" rpy="0 0 0" />
      <geometry>
        <sphere radius="0.04" />
      </geometry>
    </collision>
    <collision>
      <origin xyz="-0.031 0 -0.09" rpy="0 0 0" />
      <geometry>
        <sphere radius="0.04" />
      </geometry>
    </collision>
    <collision>
      <origin xyz="-0.031 0 -0.132" rpy="0 0 0" />
      <geometry>
        <sphere radius="0.04" />
      </geometry>
    </collision>
  </link>

  <link name="link_right_arm_4">
    <inertial>
      <mass value="0.42508710" />
      <origin rpy="0 0 0" xyz="-0.00000011 -0.02696036 0.06182110" />
      <inertia ixx="0.00082466" ixy="0.0" ixz="0.0" iyy="0.00075398" iyz="-0.00025338"
        izz="0.00039794" />
    </inertial>

    <visual>
      <origin xyz="0 0 0" rpy="1.57079632679 0 0" />
      <geometry>
        <mesh filename="package://qr_assets/rby1_description_drake/meshes/LINK_11.obj" />
      </geometry>
    </visual>

    <collision>
      <origin xyz="0 0 0.08" rpy="0 0 0" />
      <geometry>
        <sphere radius="0.04" />
      </geometry>
    </collision>

    <collision>
      <origin xyz="0 -0.027 0.07" rpy="0 0 0" />
      <geometry>
        <sphere radius="0.04" />
      </geometry>
    </collision>

    <collision>
      <origin xyz="0 -0.032 0.05" rpy="0 0 0" />
      <geometry>
        <sphere radius="0.04" />
      </geometry>
    </collision>
    <collision>
      <origin xyz="0 -0.032 0.025" rpy="0 0 0" />
      <geometry>
        <sphere radius="0.04" />
      </geometry>
    </collision>
    <collision>
      <origin xyz="0 -0.032 0" rpy="0 0 0" />
      <geometry>
        <sphere radius="0.04" />
      </geometry>
    </collision>
  </link>

  <link name="link_right_arm_5">
    <inertial>
      <mass value="1.59194395" />
      <origin rpy="0 0 0" xyz="0.00318034 -0.00532264 -0.02809655" />
      <inertia ixx="0.00256054" ixy="-0.00002344" ixz="-0.00001563" iyy="0.00257233"
        iyz="0.00021608" izz="0.00156092" />
    </inertial>

    <visual>
      <origin xyz="0 0 0" rpy="1.57079632679 0 0" />
      <geometry>
        <mesh filename="package://qr_assets/rby1_description_drake/meshes/LINK_12.obj" />
      </geometry>
    </visual>

    <collision>
      <origin xyz="0.02 0 -0.021" rpy="0 0 0" />
      <geometry>
        <sphere radius="0.065" />
      </geometry>
    </collision>

    <collision>
      <origin xyz="0 0.04 0" rpy="0 0 0" />
      <geometry>
        <sphere radius="0.04" />
      </geometry>
    </collision>

    <collision>
      <origin xyz="0 0 -0.057" rpy="0 0 0" />
      <geometry>
        <sphere radius="0.05" />
      </geometry>
    </collision>
  </link>

  <link name="link_right_arm_6">
    <inertial>
      <mass value="0.21137279" />
      <origin rpy="0 0 0" xyz="0.00066810 -0.00031708 -0.09636043" />
      <inertia ixx="0.00013511" ixy="-0.00000242" ixz="-0.00000102" iyy="0.00014453"
        iyz="0.00000094" izz="0.00025431" />
    </inertial>

    <visual>
      <origin xyz="0 0 0" rpy="1.57079632679 0 0" />
      <geometry>
        <mesh filename="package://qr_assets/rby1_description_drake/meshes/LINK_13.obj" />
      </geometry>
    </visual>

    <collision>
      <origin xyz="0 0 -0.1" rpy="0 0 0" />
      <geometry>
        <sphere radius="0.05" />
      </geometry>
    </collision>
  </link>

  <link name="FT_sensor_R">
    <inertial>
      <mass value="0.49078507" />
      <origin rpy="0 0 0" xyz="0.00010423 0.00108019 -0.01880676" />
      <inertia ixx="0.00028587" ixy="-0.00000146" ixz="-0.00000026" iyy="0.00030459"
        iyz="-0.00000772" izz="0.00036377" />
    </inertial>

    <visual>
      <origin xyz="0 0 0" rpy="1.57079632679 0 0" />
      <geometry>
        <mesh filename="package://qr_assets/rby1_description_drake/meshes/FT_SENSOR_R.obj" />
      </geometry>
    </visual>

    <collision>
      <origin xyz="0 0 -0.0275" rpy="0 0 0" />
      <geometry>
        <sphere radius="0.04" />
      </geometry>
    </collision>
  </link>

  <link name="ee_right" />

  <!-- Joints -->

  <joint name="right_arm_0" type="revolute">
    <parent link="link_right_arm_base" />
    <child link="link_right_arm_0" />
    <origin rpy="-0.349065850  0.0 0.0" xyz="0.0 -0.220 0.080073451539 " />
    <axis xyz="0 1 0" />
    <limit effort="1000.0" lower="-2.35619449" upper="2.35619449" velocity="3.14159265"
      drake:acceleration="3.141592" />
  </joint>

  <joint name="right_arm_1" type="revolute">
    <parent link="link_right_arm_0" />
    <child link="link_right_arm_1" />
    <origin rpy="0.349065850 0.0 0.0" xyz="0.0 0.0 0.0" />
    <axis xyz="1 0 0" />
    <limit effort="1000.0" lower="-3.14159265" upper="0.05" velocity="3.14159265"
      drake:acceleration="3.141592" />
  </joint>

  <joint name="right_arm_2" type="revolute">
    <parent link="link_right_arm_1" />
    <child link="link_right_arm_2" />
    <origin rpy="0.0 0.0 0.0" xyz="0.0 0.0 0.0" />
    <axis xyz="0 0 1" />
    <limit effort="1000.0" lower="-2.09439510" upper="2.09439510" velocity="3.14159265"
      drake:acceleration="3.141592" />
  </joint>

  <joint name="right_arm_3" type="revolute">
    <parent link="link_right_arm_2" />
    <child link="link_right_arm_3" />
    <origin rpy="0.0 0.0 0.0" xyz="0.031 0.0 -0.276" />
    <axis xyz="0 1 0" />
    <limit effort="1000.0" lower="-2.61799388" upper="0.01" velocity="3.14159265"
      drake:acceleration="3.141592" />
  </joint>

  <joint name="right_arm_4" type="revolute">
    <parent link="link_right_arm_3" />
    <child link="link_right_arm_4" />
    <origin rpy="0.0 0.0 0.0" xyz="-0.031 0.0 -0.256" />
    <axis xyz="0 0 1" />
    <limit effort="1000.0" lower="-6.28318531" upper="6.28318531" velocity="3.14159265"
      drake:acceleration="3.141592" />
  </joint>

  <joint name="right_arm_5" type="revolute">
    <parent link="link_right_arm_4" />
    <child link="link_right_arm_5" />
    <origin rpy="0.0 0.0 0.0" xyz="0.0 0.0 0.0" />
    <axis xyz="0 1 0" />
    <limit effort="1000.0" lower="-1.74532925" upper="2.00712864" velocity="3.14159265"
      drake:acceleration="3.141592" />
  </joint>

  <joint name="right_arm_6" type="revolute">
    <parent link="link_right_arm_5" />
    <child link="link_right_arm_6" />
    <origin rpy="0.0 0.0 0.0" xyz="0.0 0.0 0.0" />
    <axis xyz="0 0 1" />
    <limit effort="1000.0" lower="-2.96705973" upper="2.96705973" velocity="3.14159265"
      drake:acceleration="3.141592" />
  </joint>

  <joint name="tool_right" type="fixed">
    <parent link="link_right_arm_6" />
    <child link="FT_sensor_R" />
    <origin rpy="0.0 0.0 0.0" xyz="0.0 0.0 -0.1087" />
    <axis xyz="0 0 1" />
  </joint>

  <joint name="FT_Sensor_END_right" type="fixed">
    <parent link="FT_sensor_R" />
    <child link="ee_right" />
    <origin rpy="0.0 0.0 0.0" xyz="0.0 0.0 -0.0461" />
    <axis xyz="0 0 1" />
  </joint>

  <!-- Transmissions -->

  <transmission name="right_arm_0_transmission">
    <type>transmission_interface/SimpleTransmission</type>
    <joint name="right_arm_0">
      <hardwareInterface>PositionJointInterface</hardwareInterface>
    </joint>
    <actuator name="right_arm_0_motor">
      <hardwareInterface>PositionJointInterface</hardwareInterface>
      <mechanicalReduction>1</mechanicalReduction>
    </actuator>
  </transmission>

  <transmission name="right_arm_1_transmission">
    <type>transmission_interface/SimpleTransmission</type>
    <joint name="right_arm_1">
      <hardwareInterface>PositionJointInterface</hardwareInterface>
    </joint>
    <actuator name="right_arm_1_motor">
      <hardwareInterface>PositionJointInterface</hardwareInterface>
      <mechanicalReduction>1</mechanicalReduction>
    </actuator>
  </transmission>

  <transmission name="right_arm_2_transmission">
    <type>transmission_interface/SimpleTransmission</type>
    <joint name="right_arm_2">
      <hardwareInterface>PositionJointInterface</hardwareInterface>
    </joint>
    <actuator name="right_arm_2_motor">
      <hardwareInterface>PositionJointInterface</hardwareInterface>
      <mechanicalReduction>1</mechanicalReduction>
    </actuator>
  </transmission>

  <transmission name="right_arm_3_transmission">
    <type>transmission_interface/SimpleTransmission</type>
    <joint name="right_arm_3">
      <hardwareInterface>PositionJointInterface</hardwareInterface>
    </joint>
    <actuator name="right_arm_3_motor">
      <hardwareInterface>PositionJointInterface</hardwareInterface>
      <mechanicalReduction>1</mechanicalReduction>
    </actuator>
  </transmission>

  <transmission name="right_arm_4_transmission">
    <type>transmission_interface/SimpleTransmission</type>
    <joint name="right_arm_4">
      <hardwareInterface>PositionJointInterface</hardwareInterface>
    </joint>
    <actuator name="right_arm_4_motor">
      <hardwareInterface>PositionJointInterface</hardwareInterface>
      <mechanicalReduction>1</mechanicalReduction>
    </actuator>
  </transmission>

  <transmission name="right_arm_5_transmission">
    <type>transmission_interface/SimpleTransmission</type>
    <joint name="right_arm_5">
      <hardwareInterface>PositionJointInterface</hardwareInterface>
    </joint>
    <actuator name="right_arm_5_motor">
      <hardwareInterface>PositionJointInterface</hardwareInterface>
      <mechanicalReduction>1</mechanicalReduction>
    </actuator>
  </transmission>

  <transmission name="right_arm_6_transmission">
    <type>transmission_interface/SimpleTransmission</type>
    <joint name="right_arm_6">
      <hardwareInterface>PositionJointInterface</hardwareInterface>
    </joint>
    <actuator name="right_arm_6_motor">
      <hardwareInterface>PositionJointInterface</hardwareInterface>
      <mechanicalReduction>1</mechanicalReduction>
    </actuator>
  </transmission>

  <!-- Collision filters -->

  <!-- Upper arm/shoulder links that can't collide with the torso. -->
  <drake:collision_filter_group name="upper_arm">
    <drake:member link="link_right_arm_0"/>
    <drake:member link="link_right_arm_1"/>
    <drake:member link="link_right_arm_2"/>
  </drake:collision_filter_group>

  <!-- Main arm links that can't collide. -->
  <drake:collision_filter_group name="main_arm">
    <drake:member link="link_right_arm_0"/>
    <drake:member link="link_right_arm_1"/>
    <drake:member link="link_right_arm_2"/>
    <drake:member link="link_right_arm_3"/>
    <drake:member link="link_right_arm_4"/>
    <drake:member link="link_right_arm_5"/>
    <drake:ignored_collision_filter_group name="main_arm"/>
  </drake:collision_filter_group>

  <!-- Lower arm/wrist links that can't collide. -->
  <drake:collision_filter_group name="lower_arm">
    <drake:member link="link_right_arm_3"/>
    <drake:member link="link_right_arm_4"/>
    <drake:member link="link_right_arm_5"/>
    <drake:member link="link_right_arm_6"/>
    <drake:member link="FT_sensor_R"/>
    <drake:member link="ee_right"/>
    <drake:ignored_collision_filter_group name="lower_arm"/>
  </drake:collision_filter_group>

</robot>
